Traceback (most recent call last):
  File "c:\users\markw\anaconda3\lib\site-packages\jupyter_cache\executors\utils.py", line 56, in single_nb_execution
    record_timing=False,
  File "c:\users\markw\anaconda3\lib\site-packages\nbclient\client.py", line 1112, in execute
    return NotebookClient(nb=nb, resources=resources, km=km, **kwargs).execute()
  File "c:\users\markw\anaconda3\lib\site-packages\nbclient\util.py", line 74, in wrapped
    return just_run(coro(*args, **kwargs))
  File "c:\users\markw\anaconda3\lib\site-packages\nbclient\util.py", line 53, in just_run
    return loop.run_until_complete(coro)
  File "c:\users\markw\anaconda3\lib\asyncio\base_events.py", line 583, in run_until_complete
    return future.result()
  File "c:\users\markw\anaconda3\lib\site-packages\nbclient\client.py", line 554, in async_execute
    cell, index, execution_count=self.code_cells_executed + 1
  File "c:\users\markw\anaconda3\lib\site-packages\nbclient\client.py", line 857, in async_execute_cell
    self._check_raise_for_error(cell, exec_reply)
  File "c:\users\markw\anaconda3\lib\site-packages\nbclient\client.py", line 760, in _check_raise_for_error
    raise CellExecutionError.from_cell_and_msg(cell, exec_reply_content)
nbclient.exceptions.CellExecutionError: An error occurred while executing the following cell:
------------------
import pandas as pd

mydata = pd.load_excel ("mydatafile.xlsx", encoding="latin1")

------------------

[1;31m---------------------------------------------------------------------------[0m
[1;31mAttributeError[0m                            Traceback (most recent call last)
[1;32m<ipython-input-2-d3defe88a5ae>[0m in [0;36m<module>[1;34m[0m
[0;32m      1[0m [1;32mimport[0m [0mpandas[0m [1;32mas[0m [0mpd[0m[1;33m[0m[1;33m[0m[0m
[0;32m      2[0m [1;33m[0m[0m
[1;32m----> 3[1;33m [0mmydata[0m [1;33m=[0m [0mpd[0m[1;33m.[0m[0mload_excel[0m [1;33m([0m[1;34m"mydatafile.xlsx"[0m[1;33m,[0m [0mencoding[0m[1;33m=[0m[1;34m"latin1"[0m[1;33m)[0m[1;33m[0m[1;33m[0m[0m
[0m
[1;32m~\Anaconda3\lib\site-packages\pandas\__init__.py[0m in [0;36m__getattr__[1;34m(name)[0m
[0;32m    260[0m             [1;32mreturn[0m [0m_SparseArray[0m[1;33m[0m[1;33m[0m[0m
[0;32m    261[0m [1;33m[0m[0m
[1;32m--> 262[1;33m         [1;32mraise[0m [0mAttributeError[0m[1;33m([0m[1;34mf"module 'pandas' has no attribute '{name}'"[0m[1;33m)[0m[1;33m[0m[1;33m[0m[0m
[0m[0;32m    263[0m [1;33m[0m[0m
[0;32m    264[0m [1;33m[0m[0m

[1;31mAttributeError[0m: module 'pandas' has no attribute 'load_excel'
AttributeError: module 'pandas' has no attribute 'load_excel'

